Workbook

Sheet loose channel
B1: Aggregate+Greedy | F1: Basic Greedy | J1: Relax+Greedy | N1: Exact
B2: 1 | C2: 450 | D2: =(O2-C2)/O2 -> 0 | F2: 1 | G2: 450 | H2: =(O2-G2)/O2 -> 0 | J2: 1 | K2: 450 | L2: =(O2-K2)/O2 -> 0 | N2: 1 | O2: 450
B3: 2 | C3: 13083 | D3: =(O3-C3)/O3 -> 0 | F3: 2 | G3: 13083 | H3: =(O3-G3)/O3 -> 0 | J3: 2 | K3: 13083 | L3: =(O3-K3)/O3 -> 0 | N3: 2 | O3: 13083
B4: 3 | C4: 12180 | D4: =(O4-C4)/O4 -> 0 | F4: 3 | G4: 11892 | H4: =(O4-G4)/O4 -> 0.02364532 | J4: 3 | K4: 12180 | L4: =(O4-K4)/O4 -> 0 | N4: 3 | O4: 12180
B5: 4 | C5: 63096 | D5: =(O5-C5)/O5 -> 0 | F5: 4 | G5: 63096 | H5: =(O5-G5)/O5 -> 0 | J5: 4 | K5: 63096 | L5: =(O5-K5)/O5 -> 0 | N5: 4 | O5: 63096
B6: 5 | C6: 69978 | D6: =(O6-C6)/O6 -> 0 | F6: 5 | G6: 64710 | H6: =(O6-G6)/O6 -> 0.075280803 | J6: 5 | K6: 69978 | L6: =(O6-K6)/O6 -> 0 | N6: 5 | O6: 69978
B7: 6 | C7: 215581 | D7: =(O7-C7)/O7 -> 0 | F7: 6 | G7: 186598 | H7: =(O7-G7)/O7 -> 0.13444135 | J7: 6 | K7: 215581 | L7: =(O7-K7)/O7 -> 0 | N7: 6 | O7: 215581
B8: 7 | C8: 74664 | D8: =(O8-C8)/O8 -> 0 | F8: 7 | G8: 53481 | H8: =(O8-G8)/O8 -> 0.28371103 | J8: 7 | K8: 74664 | L8: =(O8-K8)/O8 -> 0 | N8: 7 | O8: 74664
B9: 8 | C9: 340171 | D9: =(O9-C9)/O9 -> 0.0043785323 | F9: 8 | G9: 324253 | H9: =(O9-G9)/O9 -> 0.050967755 | J9: 8 | K9: 341667 | L9: =(O9-K9)/O9 -> 0 | N9: 8 | O9: 341667
B10: 9 | C10: 697042 | D10: =(O10-C10)/O10 -> 0.012011067 | F10: 9 | G10: 658443 | H10: =(O10-G10)/O10 -> 0.066721378 | J10: 9 | K10: 704460 | L10: =(O10-K10)/O10 -> 0.0014967768 | N10: 9 | O10: 705516
B11: 10 | C11: 1672414 | D11: =(O11-C11)/O11 -> 0.00026780452 | F11: 10 | G11: 1444858 | H11: =(O11-G11)/O11 -> 0.13629576 | J11: 10 | K11: 1672762 | L11: =(O11-K11)/O11 -> 5.9777794e-05 | N11: 10 | O11: 1672862
B12: 11 | C12: 1158970 | D12: =(O12-C12)/O12 -> 0.0017880429 | F12: 11 | G12: 858146 | H12: =(O12-G12)/O12 -> 0.26088544 | J12: 11 | K12: 1160295 | L12: =(O12-K12)/O12 -> 0.00064683053 | N12: 11 | O12: 1161046
B13: 12 | C13: 1968454 | D13: =(O13-C13)/O13 -> 0.0070048529 | F13: 12 | G13: 1729604 | H13: =(O13-G13)/O13 -> 0.12749377 | J13: 12 | K13: 1978269 | L13: =(O13-K13)/O13 -> 0.0020536336 | N13: 12 | O13: 1982340
... B46: 45 | C46: 272940000 | D46: =(O46-C46)/O46 -> 0.00194134 | F46: 45 | G46: 173694262 | H46: =(O46-G46)/O46 -> 0.36485285 | J46: 45 | K46: 272940000 | L46: =(O46-K46)/O46 -> 0.00194134 | N46: 45 | O46: 273470900

Sheet Durations
B3: Instance | C3: BIP | D3: Basic Greedy | E3: Aggregate+Greedy | F3: Relax+Greedy | I3: Instance | J3: BIP | K3: Basic Greedy | L3: Aggregate+Greedy | M3: Relax+Greedy
B4: 1 | C4: 0.07 | D4: 0.02 | E4: 0.01 | F4: 0.09 | I4: 1 | J4: 0.1 | K4: 0.02 | L4: 0.01 | M4: 0.13
B5: 2 | C5: 1.08 | D5: 0.01 | E5: 0.01 | F5: 0.96 | I5: 2 | J5: 1.55 | K5: 0.01 | L5: 0.01 | M5: 1.58
B6: 3 | C6: 2.34 | D6: 0.1 | E6: 0.09 | F6: 2.14 | I6: 3 | J6: 3.51 | K6: 0.15 | L6: 0.09 | M6: 2.88
B7: 4 | C7: 4.01 | D7: 0.09 | E7: 0.1 | F7: 3.67 | I7: 4 | J7: 6.32 | K7: 0.07 | L7: 0.16 | M7: 5.09
B8: 5 | C8: 10.42 | D8: 0.36 | E8: 0.37 | F8: 11.05 | I8: 5 | J8: 12.26 | K8: 0.45 | L8: 0.61 | M8: 15.3
B9: 6 | C9: 18.23 | D9: 0.59 | E9: 0.75 | F9: 15.72 | I9: 6 | J9: 22.96 | K9: 0.62 | L9: 0.79 | M9: 16.74
B10: 7 | C10: 23.13 | D10: 1 | E10: 2.01 | F10: 21.58 | I10: 7 | J10: 23.9 | K10: 1.55 | L10: 3.01 | M10: 27.34
B11: 8 | C11: 44.67 | D11: 1.91 | E11: 2.59 | F11: 38.44 | I11: 8 | J11: 63.76 | K11: 2.78 | L11: 2.69 | M11: 56.73
B12: 9 | C12: 94.8 | D12: 4.8 | E12: 6.06 | F12: 105.75 | I12: 9 | J12: 95.75 | K12: 7.73 | L12: 6.86 | M12: 106.88
B13: 10 | C13: 128.7 | D13: 5.27 | E13: 7.25 | F13: 145.21 | I13: 10 | J13: 123.14 | K13: 6.01 | L13: 6.9 | M13: 183.1
B14: 11 | C14: 223.15 | D14: 14.34 | E14: 11.68 | F14: 205.07 | I14: 11 | J14: 216.93 | K14: 23.09 | L14: 16.9 | M14: 219.84
B15: 12 | C15: 244.34 | D15: 17.21 | E15: 17.29 | F15: 246.77 | I15: 12 | J15: 326.15 | K15: 23.32 | L15: 14.66 | M15: 238.67
... B20: 17 | C20: 4728.46 | D20: 563.04 | E20: 584.21 | F20: 1601.06 | I20: 17 | J20: 4757.93 | K20: 514.65 | L20: 597.01 | M20: 1667.61
B21: 18 | C21: 7368.02 | D21: 931.80207 | E21: 794.05638 | F21: 1842.005 | I21: 18 | J21: 7237.22 | K21: 820.95 | L21: 806.84
B22: 19 | C22: 8126.41 | D22: 1062.0897 | E22: 891.66884 | F22: 2024.9307 | I22: 19 | J22: 8230.33 | K22: 1146.81 | L22: 946.38
B23: 20 | C23: 11567.48 | D23: 1341.1563 | E23: 1014.0218 | F23: 2885.6571 | I23: 20 | J23: 11546.01 | K23: 1405.79 | L23: 1130.47
B24: 21 | C24: 14750.15 | D24: 1617.7397 | E24: 1291.6183 | F24: 3669.171 | I24: 21 | J24: 15387.76 | K24: 1716.53 | L24: 1214.83
B25: 22 | C25: 16961.64 | D25: 2007.9908 | E25: 1564.7981 | F25: 4231.3502 | I25: 22 | J25: 17285.5 | K25: 2198.01 | L25: 1589.85
B26: 23 | C26: 20276.98 | D26: 2408.8491 | E26: 1930.7686 | F26: 5047.2648 | I26: 23 | J26: 21152.79 | K26: 2662.03 | L26: 1943.48
B27: 24 | C27: 20687.15 | D27: 2781.7906 | E27: 2315.6064 | F27: 5146.4722 | I27: 24 | J27: 22969.43 | K27: 2893.65 | L27: 2495.72
B28: 25 | C28: 23317.34 | D28: 3053.0651 | E28: 2650.7883 | F28: 5819.3676 | I28: 25 | J28: 25207.07 | K28: 3058.61 | L28: 2908.53
B29: 26 | C29: 27289.34 | D29: 3337.2335 | E29: 2914.525 | F29: 6793.2156 | I29: 26 | J29: 29762.09 | K29: 3471.28 | L29: 3239.02
B30: 27 | C30: 29017.82 | D30: 3722.8431 | E30: 3201.1962 | F30: 7253.8256 | I30: 27 | J30: 31975.25 | K30: 3748.22 | L30: 3381.93
B31: 28 | C31: 38582.65 | D31: 4306.7552 | E31: 3558.911 | F31: 9607.4606 | I31: 28 | J31: 39471.96 | K31: 4326.14 | L31: 3821.65
B32: 29 | C32: 43735.08 | D32: 4848.2668 | E32: 4159.9571 | F32: 10921.384 | I32: 29 | J32: 43700.99 | K32: 4900.36 | L32: 4109.79
... B48: 45 | C48: 133405.38 | D48: 17148.942 | E48: 15571.332 | F48: 33238.828 | I48: 45 | J48: 194458.68 | K48: 17626.03 | L48: 16546.47

Sheet strict channel
A1: Aggregate+Greedy | E1: Basic Greedy | I1: Relax+Greedy | M1: Exact | P1: Upper Bound
A2: 1 | B2: 90 | C2: =(N2-B2)/N2 -> 0 | E2: 1 | F2: 90 | G2: =(N2-F2)/N2 -> 0 | I2: 1 | J2: 90 | K2: =(N2-J2)/N2 -> 0 | M2: 1 | N2: 90 | P2: 1 | Q2: 90 | R2: =(Q2-N2)/Q2 -> 0
A3: 2 | B3: 2510 | C3: =(N3-B3)/N3 -> 0.03609831 | E3: 2 | F3: 2510 | G3: =(N3-F3)/N3 -> 0.03609831 | I3: 2 | J3: 2604 | K3: =(N3-J3)/N3 -> 0 | M3: 2 | N3: 2604 | P3: 2 | Q3: 2604 | R3: =(Q3-N3)/Q3 -> 0
A4: 3 | B4: 5390 | C4: =(N4-B4)/N4 -> 0 | E4: 3 | F4: 5390 | G4: =(N4-F4)/N4 -> 0 | I4: 3 | J4: 5390 | K4: =(N4-J4)/N4 -> 0 | M4: 3 | N4: 5390 | P4: 3 | Q4: 5390 | R4: =(Q4-N4)/Q4 -> 0
A5: 4 | B5: 7166 | C5: =(N5-B5)/N5 -> 0.047581074 | E5: 4 | F5: 7166 | G5: =(N5-F5)/N5 -> 0.047581074 | I5: 4 | J5: 7524 | K5: =(N5-J5)/N5 -> 0 | M5: 4 | N5: 7524 | P5: 4 | Q5: 7524 | R5: =(Q5-N5)/Q5 -> 0
A6: 5 | B6: 7650 | C6: =(N6-B6)/N6 -> 0.081632653 | E6: 5 | F6: 7650 | G6: =(N6-F6)/N6 -> 0.081632653 | I6: 5 | J6: 8330 | K6: =(N6-J6)/N6 -> 0 | M6: 5 | N6: 8330 | P6: 5 | Q6: 8330 | R6: =(Q6-N6)/Q6 -> 0
A7: 6 | B7: 33368 | C7: =(N7-B7)/N7 -> 0.017142857 | E7: 6 | F7: 33368 | G7: =(N7-F7)/N7 -> 0.017142857 | I7: 6 | J7: 33924 | K7: =(N7-J7)/N7 -> 0.00076583211 | M7: 6 | N7: 33950 | P7: 6 | Q7: 33950 | R7: =(Q7-N7)/Q7 -> 0
A8: 7 | B8: 20017 | C8: =(N8-B8)/N8 -> 0.0036336486 | E8: 7 | F8: 17302 | G8: =(N8-F8)/N8 -> 0.13877551 | I8: 7 | J8: 20090 | K8: =(N8-J8)/N8 -> 0 | M8: 7 | N8: 20090 | P8: 7 | Q8: 20090 | R8: =(Q8-N8)/Q8 -> 0
A9: 8 | B9: 29870 | C9: =(N9-B9)/N9 -> 0.042628205 | E9: 8 | F9: 23643 | G9: =(N9-F9)/N9 -> 0.24221154 | I9: 8 | J9: 31200 | K9: =(N9-J9)/N9 -> 0 | M9: 8 | N9: 31200 | P9: 8 | Q9: 31200 | R9: =(Q9-N9)/Q9 -> 0
A10: 9 | B10: 52355 | C10: =(N10-B10)/N10 -> 0.032612712 | E10: 9 | F10: 52355 | G10: =(N10-F10)/N10 -> 0.032612712 | I10: 9 | J10: 53820 | K10: =(N10-J10)/N10 -> 0.0055432373 | M10: 9 | N10: 54120 | P10: 9 | Q10: 54120 | R10: =(Q10-N10)/Q10 -> 0
A11: 10 | B11: 112278 | C11: =(N11-B11)/N11 -> 0.068541563 | E11: 10 | F11: 93396 | G11: =(N11-F11)/N11 -> 0.22518666 | I11: 10 | J11: 119210 | K11: =(N11-J11)/N11 -> 0.011033682 | M11: 10 | N11: 120540 | P11: 10 | Q11: 120540 | R11: =(Q11-N11)/Q11 -> 0
A12: 11 | B12: 150407 | C12: =(N12-B12)/N12 -> 0.1189843 | E12: 11 | F12: 120365 | G12: =(N12-F12)/N12 -> 0.29495665 | I12: 11 | J12: 170720 | K12: =(N12-J12)/N12 -> 0 | M12: 11 | N12: 170720 | P12: 11 | Q12: 170720 | R12: =(Q12-N12)/Q12 -> 0
A13: 12 | B13: 114776 | C13: =(N13-B13)/N13 -> 0.14696395 | E13: 12 | F13: 99345 | G13: =(N13-F13)/N13 -> 0.26164994 | I13: 12 | J13: 133620 | K13: =(N13-J13)/N13 -> 0.0069119287 | M13: 12 | N13: 134550 | P13: 12 | Q13: 134550 | R13: =(Q13-N13)/Q13 -> 0
... A18: 17 | B18: 706083 | C18: =(N18-B18)/N18 -> 0.085621601 | E18: 17 | F18: 706083 | G18: =(N18-F18)/N18 -> 0.085621601 | I18: 17 | J18: 771800 | K18: =(N18-J18)/N18 -> 0.00051800052 | M18: 17 | N18: 772200 | P18: 17 | Q18: 772200 | R18: =(Q18-N18)/Q18 -> 0
A19: 18 | B19: 860252 | C19: =(Q19-B19)/Q19 -> 0.1052556 | E19: 18 | F19: 780472 | G19: =(Q19-F19)/Q19 -> 0.18823444 | I19: 18 | M19: 18 | Q19: 961450
A20: 19 | B20: 964500 | C20: =(Q20-B20)/Q20 -> 0.10727508 | E20: 19 | F20: 792367 | G20: =(Q20-F20)/Q20 -> 0.26659848 | I20: 19 | M20: 19 | Q20: 1080400
A21: 20 | B21: 959900 | C21: =(Q21-B21)/Q21 -> 0.061454721 | E21: 20 | F21: 597265 | G21: =(Q21-F21)/Q21 -> 0.41602225 | I21: 20 | M21: 20 | Q21: 1022753
A22: 21 | B22: 1921000 | C22: =(Q22-B22)/Q22 -> 0.061152637 | E22: 21 | F22: 883314 | G22: =(Q22-F22)/Q22 -> 0.56829931 | I22: 21 | M22: 21 | Q22: 2046126
A23: 22 | B23: 2898000 | C23: =(Q23-B23)/Q23 -> 0.05674625 | E23: 22 | F23: 1599535 | G23: =(Q23-F23)/Q23 -> 0.47937633 | I23: 22 | M23: 22 | Q23: 3072344
A24: 23 | B24: 3610000 | C24: =(Q24-B24)/Q24 -> 0.11914073 | E24: 23 | F24: 2662337 | G24: =(Q24-F24)/Q24 -> 0.35037556 | I24: 23 | M24: 23 | Q24: 4098271
A25: 24 | B25: 4878000 | C25: =(Q25-B25)/Q25 -> 0.047842127 | E25: 24 | F25: 2729581 | G25: =(Q25-F25)/Q25 -> 0.4672013 | I25: 24 | M25: 24 | Q25: 5123100
A26: 25 | B26: 5266000 | C26: =(Q26-B26)/Q26 -> 0.14354738 | E26: 25 | F26: 3466977 | G26: =(Q26-F26)/Q26 -> 0.43613719 | I26: 25 | M26: 25 | Q26: 6148618
A27: 26 | B27: 6374144 | C27: =(Q27-B27)/Q27 -> 0.11147304 | E27: 26 | F27: 4286262 | G27: =(Q27-F27)/Q27 -> 0.40251439 | I27: 26 | M27: 26 | Q27: 7173833
A28: 27 | B28: 7632349 | C28: =(Q28-B28)/Q28 -> 0.069284072 | E28: 27 | F28: 4495396 | G28: =(Q28-F28)/Q28 -> 0.45181534 | I28: 27 | M28: 27 | Q28: 8200514
A29: 28 | B29: 7975923 | C29: =(Q29-B29)/Q29 -> 0.13566571 | E29: 28 | F29: 5502254 | G29: =(Q29-F29)/Q29 -> 0.4037321 | I29: 28 | M29: 28 | Q29: 9227822
A30: 29 | B30: 9732065 | C30: =(Q30-B30)/Q30 -> 0.050376915 | E30: 29 | F30: 6276007 | G30: =(Q30-F30)/Q30 -> 0.38760776 | I30: 29 | M30: 29 | Q30: 10248345
... A46: 45 | B46: 284063971 | C46: =(Q46-B46)/Q46 -> 0.10172488 | E46: 45 | F46: 150825577 | G46: =(Q46-F46)/Q46 -> 0.52305509 | I46: 45 | M46: 45 | Q46: 316232704

Sheet Sheet1
A1: Instance | B1: Gap %
A2: 1 | B2: 0
A3: 2 | B3: 0
A4: 3 | B4: 0.350602
A5: 4 | B5: 0.5
A6: 5 | B6: 0.8
A7: 6 | B7: 0.82652
A8: 7 | B8: 0.730928
A9: 8 | B9: 0.884667
A10: 9 | B10: 0.92329
A11: 10 | B11: 0.927944
A12: 11 | B12: 0.85296
A13: 12 | B13: 0.932126
... A18: 17 | B18: 0.930291
A19: average | B19: =AVERAGE(B6:B18) -> 0.88261923

Sheet NetworkingEXX
D2: Exact | I2: Greed With Alg-A | N2: Greed With Alg-B | S2: Greed With Alg-C
A3: Campaign | B3: Customer | D3: Duration | E3: Objective Value | F3: Direct Message | G3: edges | I3: Duration | J3: Objective Value | K3: Direct Messages | L3: edges | N3: Duration | O3: Objective Value | P3: Direct Messages | Q3: edges | S3: Duration | T3: Objective Value | U3: Direct Messages | V3: edges
A4: 1 | B4: 10 | D4: 0.02 | E4: 450 | F4: 5 | G4: 0 | I4: 1.82 | J4: 450 | K4: 5 | L4: 0 | N4: 1.92 | O4: 450 | P4: 5 | Q4: 0 | S4: 1.62 | T4: 450 | U4: 5 | V4: 0
A5: 2 | B5: 100 | D5: 0.14 | E5: 5390 | F5: 97 | G5: 0 | I5: 0 | J5: 4067 | K5: 1260 | L5: 0 | N5: 0 | O5: 4067 | P5: 1260 | Q5: 0 | S5: 0.03 | T5: 4067 | U5: 1260 | V5: 0
A6: 5 | B6: 100 | D6: 0.27 | E6: 10498 | F6: 255 | G6: 0 | I6: 0 | J6: 3290 | K6: 1220 | L6: 0 | N6: 0 | O6: 3290 | P6: 1220 | Q6: 0 | S6: 0.06 | T6: 3290 | U6: 1220 | V6: 0
A7: 5 | B7: 200 | D7: 0.58 | E7: 30727 | F7: 499 | G7: 6 | I7: 0.01 | J7: 13002 | K7: 2600 | L7: 6 | N7: 0.01 | O7: 13002 | P7: 2600 | Q7: 6 | S7: 0.1 | T7: 13002 | U7: 2600 | V7: 6
A8: 5 | B8: 500 | D8: 1.61 | E8: 37466 | F8: 1219 | G8: 34 | I8: 0.07 | J8: 12580 | K8: 5950 | L8: 34 | N8: 0.09 | O8: 12580 | P8: 5950 | Q8: 34 | S8: 0.36 | T8: 12580 | U8: 5950 | V8: 34
A9: 5 | B9: 700 | D9: 2.43 | E9: 128020 | F9: 1714 | G9: 72 | I9: 0.14 | J9: 46255 | K9: 8258 | L9: 72 | N9: 0.19 | O9: 46187 | P9: 8258 | Q9: 72 | S9: 0.64 | T9: 46187 | U9: 8258 | V9: 72
A10: 5 | B10: 1000 | D10: 4.11 | E10: 35796 | F10: 2395 | G10: 138 | I10: 0.28 | J10: 22664 | K10: 11900 | L10: 138 | N10: 0.39 | O10: 22678 | P10: 11900 | Q10: 138 | S10: 1.23 | T10: 22657 | U10: 11900 | V10: 138
A11: 10 | B11: 1000 | D11: 8.14 | E11: 270940 | F11: 4867 | G11: 138 | I11: 0.91 | J11: 49660 | K11: 12000 | L11: 138 | N11: 0.97 | O11: 50050 | P11: 12000 | Q11: 138 | S11: 2.9 | T11: 49855 | U11: 12000 | V11: 138
A12: 10 | B12: 2000 | D12: 28.31 | E12: 702573 | F12: 9406 | G12: 558 | I12: 3.6 | J12: 111012 | K12: 25400 | L12: 558 | N12: 3.91 | O12: 111078 | P12: 25400 | Q12: 558 | S12: 11.14 | T12: 110352 | U12: 25400 | V12: 558
A13: 10 | B13: 3000 | D13: 75.34 | E13: 1033112 | F13: 13507 | G13: 1326 | I13: 8.04 | J13: 268814 | K13: 38100 | L13: 1326 | N13: 8.74 | O13: 268520 | P13: 38100 | Q13: 1326 | S13: 25.47 | T13: 263032 | U13: 38100 | V13: 1326
A14: 10 | B14: 4000 | D14: 167.71 | E14: 1194109 | F14: 17566 | G14: 2398 | I14: 14.34 | J14: 375584 | K14: 49600 | L14: 2398 | N14: 16.02 | O14: 376457 | P14: 49600 | Q14: 2398 | S14: 46.91 | T14: 370540 | U14: 49600 | V14: 2398
A15: 10 | B15: 5000 | D15: 307.84 | E15: 1738544 | F15: 21412 | G15: 3762 | I15: 22.04 | J15: 354660 | K15: 64500 | L15: 3762 | N15: 27.33 | O15: 353694 | P15: 64500 | Q15: 3762 | S15: 77.75 | T15: 345552 | U15: 64500 | V15: 3762
A16: 10 | B16: 10000 | D16: 2271.01 | E16: 4660587 | F16: 39863 | G16: 14972 | I16: 155.44 | J16: 861424 | K16: 121000 | L16: 14972 | N16: 185.54 | O16: 859044 | P16: 121000 | Q16: 14972 | S16: 500.6 | T16: 822868 | U16: 121000 | V16: 14972
A17: 10 | B17: 15000 | I17: 702.25 | J17: 1589216 | K17: 181500 | L17: 33712 | N17: 721.18 | O17: 1583008 | P17: 181500 | Q17: 33712 | S17: 1732.8 | T17: 1510944 | U17: 181500 | V17: 33712
A18: 10 | B18: 20000 | I18: 1490.33 | J18: 1744120 | K18: 250000 | L18: 59762 | N18: 1505.61 | O18: 1740592 | P18: 250000 | Q18: 59762

Sheet NetworkingLESS
E2: Exact | K2: Greed With Alg-A | S2: Greed With Alg-B | AA2: Greed With Alg-C | AH2: SA+Greed With Alg-C | AN2: Exact/NO - NET | AT2: SA+Greed With Alg-C/NO - NET
A3: Instance | B3: Campaign | C3: Customer | E3: Duration | F3: Objective Value | G3: Direct Messages | H3: edges | I3: OV/DM | K3: Duration | L3: Objective Value | M3: Direct Messages | N3: OV Diff | O3: OV-C Diff | P3: OV-S Diff | Q3: OV/DM | S3: Duration | T3: Objective Value | U3: Direct Messages | V3: OV Diff | W3: OV-C Diff | X3: OV-S Diff | Y3: OV/DM | AA3: Duration | AB3: Objective Value | AC3: Direct Messages | AD3: OV Diff | AE3: OV-S Diff | AF3: OV/DM | AH3: Duration | AI3: Objective Value | AJ3: Direct Messages | AK3: OV Diff | AL3: OV/DM | AN3: Objective Value No Net | AO3: Objective Value Net Applied | AP3: MaxDegree | AQ3: AverageDegre | AR3: Net Ratio | AT3: Objective Value | AU3: Net Ratio
A4: 0 | B4: 1 | C4: 10 | E4: 0.01 | F4: 450 | G4: 5 | H4: 0 | I4: =F4/G4 -> 90 | K4: 1.87 | L4: 450 | M4: 5 | N4: =($F4-L4)/$F4 -> 0 | O4: =($AB4-L4)/$AB4 -> 0 | P4: =($AI4-L4)/$AI4 -> 0 | Q4: =L4/M4 -> 90 | S4: 1.86 | T4: 450 | U4: 5 | V4: =($F4-T4)/$F4 -> 0 | W4: =($AB4-T4)/$AB4 -> 0 | X4: =($AI4-T4)/$AI4 -> 0 | Y4: =T4/U4 -> 90 | AA4: 1.84 | AB4: 450 | AC4: 5 | AD4: =($F4-AB4)/$F4 -> 0 | AE4: =($AI4-AB4)/$AI4 -> 0 | AF4: =AB4/AC4 -> 90 | AH4: 1.74 | AI4: 450 | AJ4: 5 | AK4: =($F4-AI4)/$F4 -> 0 | AL4: =AI4/AJ4 -> 90
A5: 1 | B5: 2 | C5: 100 | E5: 0.02 | F5: 5390 | G5: 97 | H5: 10 | I5: =F5/G5 -> 55.56701 | K5: 0 | L5: 4067 | M5: 73 | N5: =($F5-L5)/$F5 -> 0.24545455 | O5: =($AB5-L5)/$AB5 -> 0 | P5: =($AI5-L5)/$AI5 -> 0.23119093 | Q5: =L5/M5 -> 55.712329 | S5: 0 | T5: 4067 | U5: 73 | V5: =($F5-T5)/$F5 -> 0.24545455 | W5: =($AB5-T5)/$AB5 -> 0 | X5: =($AI5-T5)/$AI5 -> 0.23119093 | Y5: =T5/U5 -> 55.712329 | AA5: 0.03 | AB5: 4067 | AC5: 73 | AD5: =($F5-AB5)/$F5 -> 0.24545455 | AE5: =($AI5-AB5)/$AI5 -> 0.23119093 | AF5: =AB5/AC5 -> 55.712329 | AH5: 3.4 | AI5: 5290 | AJ5: 95 | AK5: =($F5-AI5)/$F5 -> 0.018552876 | AL5: =AI5/AJ5 -> 55.684211 | AN5: 2510 | AO5: 4263 | AP5: 1 | AQ5: 0.1 | AR5: =F5/AO5 -> 1.2643678 | AT5: 4851 | AU5: =AI5/AT5 -> 1.0904968
A6: 2 | B6: 5 | C6: 100 | E6: 0.07 | F6: 7290 | G6: 255 | H6: 10 | I6: =F6/G6 -> 28.588235 | K6: 0 | L6: 2890 | M6: 101 | N6: =($F6-L6)/$F6 -> 0.60356653 | O6: =($AB6-L6)/$AB6 -> 0.50933786 | P6: =($AI6-L6)/$AI6 -> 0.58357349 | Q6: =L6/M6 -> 28.613861 | S6: 0 | T6: 2890 | U6: 101 | V6: =($F6-T6)/$F6 -> 0.60356653 | W6: =($AB6-T6)/$AB6 -> 0.50933786 | X6: =($AI6-T6)/$AI6 -> 0.58357349 | Y6: =T6/U6 -> 28.613861 | AA6: 0.06 | AB6: 5890 | AC6: 206 | AD6: =($F6-AB6)/$F6 -> 0.1920439 | AE6: =($AI6-AB6)/$AI6 -> 0.15129683 | AF6: =AB6/AC6 -> 28.592233 | AH6: 3.65 | AI6: 6940 | AJ6: 242 | AK6: =($F6-AI6)/$F6 -> 0.048010974 | AL6: =AI6/AJ6 -> 28.677686 | AN6: 5390 | AO6: 6170 | AP6: 1 | AQ6: 0.1 | AR6: =F6/AO6 -> 1.1815235 | AT6: 3170 | AU6: =AI6/AT6 -> 2.1892744
A7: 3 | B7: 5 | C7: 200 | E7: 0.1 | F7: 24472 | G7: 499 | H7: 52 | I7: =F7/G7 -> 49.042084 | K7: 0 | L7: 11782 | M7: 240 | N7: =($F7-L7)/$F7 -> 0.51855181 | O7: =($AB7-L7)/$AB7 -> 0.43731792 | P7: =($AI7-L7)/$AI7 -> 0.49786908 | Q7: =L7/M7 -> 49.091667 | S7: 0 | T7: 14632 | U7: 298 | V7: =($F7-T7)/$F7 -> 0.40209219 | W7: =($AB7-T7)/$AB7 -> 0.30120827 | X7: =($AI7-T7)/$AI7 -> 0.37640641 | Y7: =T7/U7 -> 49.100671 | AA7: 0.1 | AB7: 20939 | AC7: 427 | AD7: =($F7-AB7)/$F7 -> 0.14436907 | AE7: =($AI7-AB7)/$AI7 -> 0.10761166 | AF7: =AB7/AC7 -> 49.037471 | AH7: 3.85 | AI7: 23464 | AJ7: 478 | AK7: =($F7-AI7)/$F7 -> 0.041189931 | AL7: =AI7/AJ7 -> 49.087866 | AN7: 7166 | AO7: 12316 | AP7: 3 | AQ7: 0.26 | AR7: =F7/AO7 -> 1.9870088 | AT7: 7659 | AU7: =AI7/AT7 -> 3.0635853
A8: 4 | B8: 5 | C8: 500 | E8: 0.27 | F8: 29348 | G8: 1219 | H8: 284 | I8: =F8/G8 -> 24.075472 | K8: 0.02 | L8: 10880 | M8: 452 | N8: =($F8-L8)/$F8 -> 0.62927627 | O8: =($AB8-L8)/$AB8 -> 0.49699491 | P8: =($AI8-L8)/$AI8 -> 0.60357078 | Q8: =L8/M8 -> 24.070796 | S8: 0.05 | T8: 15734 | U8: 654 | V8: =($F8-T8)/$F8 -> 0.4638817 | W8: =($AB8-T8)/$AB8 -> 0.27258437 | X8: =($AI8-T8)/$AI8 -> 0.42670796 | Y8: =T8/U8 -> 24.058104 | AA8: 0.33 | AB8: 21630 | AC8: 898 | AD8: =($F8-AB8)/$F8 -> 0.26298215 | AE8: =($AI8-AB8)/$AI8 -> 0.2118783 | AF8: =AB8/AC8 -> 24.08686 | AH8: 4.95 | AI8: 27445 | AJ8: 1139 | AK8: =($F8-AI8)/$F8 -> 0.064842579 | AL8: =AI8/AJ8 -> 24.095698 | AN8: 7650 | AO8: 17578 | AP8: 4 | AQ8: 0.56 | AR8: =F8/AO8 -> 1.669587 | AT8: 8318 | AU8: =AI8/AT8 -> 3.299471
A9: 5 | B9: 5 | C9: 700 | E9: 0.41 | F9: 99280 | G9: 1714 | H9: 622 | I9: =F9/G9 -> 57.922987 | K9: 0.05 | L9: 31563 | M9: 545 | N9: =($F9-L9)/$F9 -> 0.68208098 | O9: =($AB9-L9)/$AB9 -> 0.61270017 | P9: =($AI9-L9)/$AI9 -> 0.65739314 | Q9: =L9/M9 -> 57.913761 | S9: 0.09 | T9: 40182 | U9: 694 | V9: =($F9-T9)/$F9 -> 0.59526591 | W9: =($AB9-T9)/$AB9 -> 0.50693908 | X9: =($AI9-T9)/$AI9 -> 0.56383648 | Y9: =T9/U9 -> 57.899135 | AA9: 0.57 | AB9: 81495 | AC9: 1407 | AD9: =($F9-AB9)/$F9 -> 0.17913981 | AE9: =($AI9-AB9)/$AI9 -> 0.11539631 | AF9: =AB9/AC9 -> 57.921109 | AH9: 5.4 | AI9: 92126 | AJ9: 1590 | AK9: =($F9-AI9)/$F9 -> 0.072058824 | AL9: =AI9/AJ9 -> 57.940881 | AN9: 33368 | AO9: 43100 | AP9: 5 | AQ9: 0.88 | AR9: =F9/AO9 -> 2.3034803 | AT9: 32504 | AU9: =AI9/AT9 -> 2.8342973
A10: 6 | B10: 5 | C10: 1000 | E10: 0.63 | F10: 33031 | G10: 2395 | H10: 1272 | I10: =F10/G10 -> 13.791649 | K10: 0.1 | L10: 22664 | M10: 1643 | N10: =($F10-L10)/$F10 -> 0.31385668 | O10: =($AB10-L10)/$AB10 -> 0.1497918 | P10: =($AI10-L10)/$AI10 -> 0.28897255 | Q10: =L10/M10 -> 13.794279 | S10: 0.19 | T10: 22678 | U10: 1644 | V10: =($F10-T10)/$F10 -> 0.31343284 | W10: =($AB10-T10)/$AB10 -> 0.14926661 | X10: =($AI10-T10)/$AI10 -> 0.28853333 | Y10: =T10/U10 -> 13.794404 | AA10: 1.1 | AB10: 26657 | AC10: 1933 | AD10: =($F10-AB10)/$F10 -> 0.19297024 | AE10: =($AI10-AB10)/$AI10 -> 0.16370196 | AF10: =AB10/AC10 -> 13.790481 | AH10: 10.15 | AI10: 31875 | AJ10: 2311 | AK10: =($F10-AI10)/$F10 -> 0.034997427 | AL10: =AI10/AJ10 -> 13.79273 | AN10: 20017 | AO10: 23591 | AP10: 8 | AQ10: 1.28 | AR10: =F10/AO10 -> 1.4001526 | AT10: 17749 | AU10: =AI10/AT10 -> 1.7958758
A11: 7 | B11: 10 | C11: 1000 | E11: 1.29 | F11: 115483 | G11: 4867 | H11: 1272 | I11: =F11/G11 -> 23.727758 | K11: 0.15 | L11: 34580 | M11: 1457 | N11: =($F11-L11)/$F11 -> 0.70056199 | O11: =($AB11-L11)/$AB11 -> 0.63388036 | P11: =($AI11-L11)/$AI11 -> 0.67340385 | Q11: =L11/M11 -> 23.733699 | S11: 0.24 | T11: 54775 | U11: 2308 | V11: =($F11-T11)/$F11 -> 0.52568776 | W11: =($AB11-T11)/$AB11 -> 0.42006353 | X11: =($AI11-T11)/$AI11 -> 0.48266906 | Y11: =T11/U11 -> 23.732669 | AA11: 2.24 | AB11: 94450 | AC11: 3981 | AD11: =($F11-AB11)/$F11 -> 0.1821307 | AE11: =($AI11-AB11)/$AI11 -> 0.1079524 | AF11: =AB11/AC11 -> 23.725195 | AH11: 21.8 | AI11: 105880 | AJ11: 4462 | AK11: =($F11-AI11)/$F11 -> 0.083155096 | AL11: =AI11/AJ11 -> 23.729269 | AN11: 29870 | AO11: 60450 | AP11: 8 | AQ11: 1.28 | AR11: =F11/AO11 -> 1.9103888 | AT11: 22396 | AU11: =AI11/AT11 -> 4.7276299
A12: 8 | B12: 10 | C12: 2000 | E12: 4.26 | F12: 370512 | G12: 9406 | H12: 4728 | I12: =F12/G12 -> 39.391027 | K12: 0.6 | L12: 111012 | M12: 3818 | N12: =($F12-L12)/$F12 -> 0.70038217 | O12: =($AB12-L12)/$AB12 -> 0.60402637 | P12: =($AI12-L12)/$AI12 -> 0.68408112 | Q12: =L12/M12 -> 29.075956 | S12: 0.97 | T12: 117078 | U12: 3972 | V12: =($F12-T12)/$F12 -> 0.68401023 | W12: =($AB12-T12)/$AB12 -> 0.58238928 | X12: =($AI12-T12)/$AI12 -> 0.66681844 | Y12: =T12/U12 -> 29.475831 | AA12: 8.75 | AB12: 280352 | AC12: 9117 | AD12: =($F12-AB12)/$F12 -> 0.24333895 | AE12: =($AI12-AB12)/$AI12 -> 0.20217192 | AF12: =AB12/AC12 -> 30.750466 | AH12: 79.1 | AI12: 351394 | AJ12: 8920 | AK12: =($F12-AI12)/$F12 -> 0.051598869 | AL12: =AI12/AJ12 -> 39.393946 | AN12: 52355 | AO12: 168828 | AP12: 10 | AQ12: 2.36 | AR12: =F12/AO12 -> 2.1946123 | AT12: 109494 | AU12: =AI12/AT12 -> 3.2092535
A13: 9 | B13: 10 | C13: 3000 | E13: 11.3 | F13: 799008 | G13: 13507 | H13: 10760 | I13: =F13/G13 -> 59.155105 | K13: 1.36 | L13: 268814 | M13: 9544 | N13: =($F13-L13)/$F13 -> 0.66356532 | O13: =($AB13-L13)/$AB13 -> 0.59456859 | P13: =($AI13-L13)/$AI13 -> 0.63600838 | Q13: =L13/M13 -> 28.165759 | S13: 2.18 | T13: 268520 | U13: 9439 | V13: =($F13-T13)/$F13 -> 0.66393328 | W13: =($AB13-T13)/$AB13 -> 0.59501201 | X13: =($AI13-T13)/$AI13 -> 0.63640647 | Y13: =T13/U13 -> 28.447929 | AA13: 20.1 | AB13: 663032 | AC13: 13208 | AD13: =($F13-AB13)/$F13 -> 0.17018102 | AE13: =($AI13-AB13)/$AI13 -> 0.10221159 | AF13: =AB13/AC13 -> 50.199273 | AH13: 189.75 | AI13: 738517 | AJ13: 12484 | AK13: =($F13-AI13)/$F13 -> 0.075707627 | AL13: =AI13/AJ13 -> 59.157081 | AN13: 112278 | AO13: 478828 | AP13: 12 | AQ13: 3.59 | AR13: =F13/AO13 -> 1.6686743 | AT13: 226956 | AU13: =AI13/AT13 -> 3.2540096
A14: 10 | B14: 10 | C14: 4000 | E14: 24.03 | F14: 923919 | G14: 17566 | H14: 19234 | I14: =F14/G14 -> 52.597006 | K14: 2.43 | L14: 335135 | M14: 9372 | N14: =($F14-L14)/$F14 -> 0.63726799 | O14: =($AB14-L14)/$AB14 -> 0.54139469 | P14: =($AI14-L14)/$AI14 -> 0.61640024 | Q14: =L14/M14 -> 35.759176 | S14: 3.88 | T14: 334359 | U14: 9357 | V14: =($F14-T14)/$F14 -> 0.63810789 | W14: =($AB14-T14)/$AB14 -> 0.54245659 | X14: =($AI14-T14)/$AI14 -> 0.61728846 | Y14: =T14/U14 -> 35.733568 | AA14: 37.33 | AB14: 730770 | AC14: 15894 | AD14: =($F14-AB14)/$F14 -> 0.20905404 | AE14: =($AI14-AB14)/$AI14 -> 0.16355141 | AF14: =AB14/AC14 -> 45.977727 | AH14: 331.75 | AI14: 873658 | AJ14: 16610 | AK14: =($F14-AI14)/$F14 -> 0.05439979 | AL14: =AI14/AJ14 -> 52.598314 | AN14: 150407 | AO14: 420398 | AP14: 15 | AQ14: 4.81 | AR14: =F14/AO14 -> 2.1977245 | AT14: 390761 | AU14: =AI14/AT14 -> 2.2357861
A15: 11 | B15: 10 | C15: 5000 | E15: 43.93 | F15: 1079619 | G15: 21412 | H15: 29922 | I15: =F15/G15 -> 50.421212 | K15: 3.8 | L15: 316572 | M15: 10279 | N15: =($F15-L15)/$F15 -> 0.70677433 | O15: =($AB15-L15)/$AB15 -> 0.65225701 | P15: =($AI15-L15)/$AI15 -> 0.69807902 | Q15: =L15/M15 -> 30.797938 | S15: 6.13 | T15: 315606 | U15: 10259 | V15: =($F15-T15)/$F15 -> 0.70766909 | W15: =($AB15-T15)/$AB15 -> 0.65331813 | X15: =($AI15-T15)/$AI15 -> 0.69900031 | Y15: =T15/U15 -> 30.763817 | AA15: 60.39 | AB15: 910362 | AC15: 19235 | AD15: =($F15-AB15)/$F15 -> 0.15677475 | AE15: =($AI15-AB15)/$AI15 -> 0.13176974 | AF15: =AB15/AC15 -> 47.328412 | AH15: 541.7 | AI15: 1048526 | AJ15: 20795 | AK15: =($F15-AI15)/$F15 -> 0.028799975 | AL15: =AI15/AJ15 -> 50.422025 | AN15: 114776 | AO15: 444705 | AP15: 17 | AQ15: 5.98 | AR15: =F15/AO15 -> 2.4277195 | AT15: 549158 | AU15: =AI15/AT15 -> 1.9093339
A16: 12 | B16: 10 | C16: 10000 | E16: 309.96 | F16: 3531509 | G16: 39863 | H16: 119778 | I16: =F16/G16 -> 88.59115 | K16: 15.53 | L16: 861424 | M16: 25724 | N16: =($F16-L16)/$F16 -> 0.75607481 | O16: =($AB16-L16)/$AB16 -> 0.69484085 | P16: =($AI16-L16)/$AI16 -> 0.74543396 | Q16: =L16/M16 -> 33.487172 | S16: 25.1 | T16: 859044 | U16: 24697 | V16: =($F16-T16)/$F16 -> 0.75674874 | W16: =($AB16-T16)/$AB16 -> 0.69568396 | X16: =($AI16-T16)/$AI16 -> 0.74613729 | Y16: =T16/U16 -> 34.783334 | AA16: 290.14 | AB16: 2822868 | AC16: 56864 | AD16: =($F16-AB16)/$F16 -> 0.20066238 | AE16: =($AI16-AB16)/$AI16 -> 0.16579253 | AF16: =AB16/AC16 -> 49.642445 | AH16: 2601.55 | AI16: 3383892 | AJ16: 38196 | AK16: =($F16-AI16)/$F16 -> 0.041799978 | AL16: =AI16/AJ16 -> 88.592837 | AN16: 274405 | AO16: 882776 | AP16: 27 | AQ16: 11.98 | AR16: =F16/AO16 -> 4.0004588 | AT16: 985185 | AU16: =AI16/AT16 -> 3.4347782
... A19: 15 | B19: 10 | C19: 25000 | E19: 50792.01 | F19: 12891294 | G19: 110297 | H19: 751672 | I19: =F19/G19 -> 116.87801 | K19: 109.15 | L19: 4006876 | M19: 84283 | N19: =($F19-L19)/$F19 -> 0.68917969 | O19: =($AB19-L19)/$AB19 -> 0.61575619 | P19: =($AI19-L19)/$AI19 -> 0.6704769 | Q19: =L19/M19 -> 47.540738 | S19: 168.04 | T19: 3997952 | U19: 83206 | V19: =($F19-T19)/$F19 -> 0.68987194 | W19: =($AB19-T19)/$AB19 -> 0.61661197 | X19: =($AI19-T19)/$AI19 -> 0.67121081 | Y19: =T19/U19 -> 48.048843 | AA19: 1668.64 | AB19: 10427952 | AC19: 129221 | AD19: =($F19-AB19)/$F19 -> 0.1910857 | AE19: =($AI19-AB19)/$AI19 -> 0.14241143 | AF19: =AB19/AC19 -> 80.698586 | AH19: 14829.85 | AI19: 12159621 | AJ19: 104036 | AK19: =($F19-AI19)/$F19 -> 0.056757142 | AL19: =AI19/AJ19 -> 116.87897 | AN19: 920941 | AO19: 4196220 | AP19: 55 | AQ19: 30.06 | AR19: =F19/AO19 -> 3.0721206 | AT19: 2798271 | AU19: =AI19/AT19 -> 4.3454051
A20: 16 | B20: 10 | C20: 30000 | H20: 1080640 | K20: 163.15 | L20: 6156725 | M20: 127413 | O20: =($AB20-L20)/$AB20 -> 0.52836155 | P20: =($AI20-L20)/$AI20 -> 0.60366518 | Q20: =L20/M20 -> 48.321011 | S20: 253.59 | T20: 6413256 | U20: 126607 | W20: =($AB20-T20)/$AB20 -> 0.50870988 | X20: =($AI20-T20)/$AI20 -> 0.58715117 | Y20: =T20/U20 -> 50.65483 | AA20: 2128.14 | AB20: 13053908 | AC20: 155867 | AE20: =($AI20-AB20)/$AI20 -> 0.15966389 | AF20: =AB20/AC20 -> 83.7503 | AH20: 18913.65 | AI20: 15534151 | AJ20: 150000 | AL20: =AI20/AJ20 -> 103.56101 | AO20: AVG | AR20: =AVERAGE(AR5:AR19) -> 2.6322054 | AT20: 6135807 | AU20: =AI20/AT20 -> 2.5317209
A21: 17 | B21: 10 | C21: 35000 | H21: 1470142 | K21: 231.98 | L21: 7832598 | M21: 155445 | O21: =($AB21-L21)/$AB21 -> 0.57507991 | P21: =($AI21-L21)/$AI21 -> 0.65453651 | Q21: =L21/M21 -> 50.388227 | S21: 357.76 | T21: 8158958 | U21: 154709 | W21: =($AB21-T21)/$AB21 -> 0.55737481 | X21: =($AI21-T21)/$AI21 -> 0.64014212 | Y21: =T21/U21 -> 52.737449 | AA21: 2587.64 | AB21: 18433108 | AC21: 186291 | AE21: =($AI21-AB21)/$AI21 -> 0.18699188 | AF21: =AB21/AC21 -> 98.947926 | AH21: 25256.1 | AI21: 22672723 | AJ21: 170660 | AL21: =AI21/AJ21 -> 132.85318 | AT21: 7276898 | AU21: =AI21/AT21 -> 3.1157126
A22: 18 | B22: 10 | C22: 40000 | H22: 1919224 | K22: 316.46 | L22: 11825328 | M22: 216196 | O22: =($AB22-L22)/$AB22 -> 0.57020981 | P22: =($AI22-L22)/$AI22 -> 0.66752256 | Q22: =L22/M22 -> 54.697256 | S22: 496.71 | T22: 12318050 | U22: 219719 | W22: =($AB22-T22)/$AB22 -> 0.55230189 | X22: =($AI22-T22)/$AI22 -> 0.65366933 | Y22: =T22/U22 -> 56.062744 | AA22: 3047.14 | AB22: 27514188 | AC22: 197895 | AE22: =($AI22-AB22)/$AI22 -> 0.22641918 | AF22: =AB22/AC22 -> 139.03428 | AH22: 28532.15 | AI22: 35567309 | AJ22: 195885 | AL22: =AI22/AJ22 -> 181.5724 | AT22: 18914981 | AU22: =AI22/AT22 -> 1.8803777
A23: 19 | B23: 10 | C23: 45000 | H23: 2429382 | K23: 415.75 | L23: 25355318 | M23: 420429 | O23: =($AB23-L23)/$AB23 -> 0.60378256 | P23: =($AI23-L23)/$AI23 -> 0.67254757 | Q23: =L23/M23 -> 60.308204 | S23: 653.14 | T23: 36411790 | U23: 623069 | W23: =($AB23-T23)/$AB23 -> 0.43100748 | X23: =($AI23-T23)/$AI23 -> 0.52975825 | Y23: =T23/U23 -> 58.439418 | AA23: 3506.64 | AB23: 63993442 | AC23: 294407 | AE23: =($AI23-AB23)/$AI23 -> 0.17355372 | AF23: =AB23/AC23 -> 217.36386 | AH23: 33112.9 | AI23: 77432065 | AJ23: 273766 | AL23: =AI23/AJ23 -> 282.84033 | AT23: 13045096 | AU23: =AI23/AT23 -> 5.9357221
A24: 20 | B24: 10 | C24: 50000 | H24: 3000132 | K24: 530.86 | L24: 31567586 | M24: 541163 | O24: =($AB24-L24)/$AB24 -> 0.61083767 | P24: =($AI24-L24)/$AI24 -> 0.67424732 | Q24: =L24/M24 -> 58.332861 | S24: 860.19 | T24: 32882904 | U24: 559605 | W24: =($AB24-T24)/$AB24 -> 0.59462255 | X24: =($AI24-T24)/$AI24 -> 0.66067427 | Y24: =T24/U24 -> 58.760919 | AA24: 3966.14 | AB24: 81116756 | AC24: 303410 | AE24: =($AI24-AB24)/$AI24 -> 0.16293883 | AF24: =AB24/AC24 -> 267.3503 | AH24: 39025.6 | AI24: 96906605 | AJ24: 355000 | AL24: =AI24/AJ24 -> 272.97635 | AT24: 28218359 | AU24: =AI24/AT24 -> 3.4341687
A25: 21 | B25: 10 | C25: 55000 | H25: 3628652 | K25: 672.84 | L25: 36707166 | M25: 643411 | O25: =($AB25-L25)/$AB25 -> 0.58097829 | P25: =($AI25-L25)/$AI25 -> 0.6324371 | Q25: =L25/M25 -> 57.050883 | S25: 1067.24 | T25: 38236632 | U25: 656499 | W25: =($AB25-T25)/$AB25 -> 0.56351905 | X25: =($AI25-T25)/$AI25 -> 0.61712197 | Y25: =T25/U25 -> 58.243245 | AA25: 4425.64 | AB25: 87602063 | AC25: 423297 | AE25: =($AI25-AB25)/$AI25 -> 0.12280702 | AF25: =AB25/AC25 -> 206.95177 | AH25: 41087.9 | AI25: 99866352 | AJ25: 342653 | AL25: =AI25/AJ25 -> 291.45039 | AT25: 46782944 | AU25: =AI25/AT25 -> 2.1346744
A26: 22 | B26: 10 | C26: 60000 | H26: 4319934 | K26: 838.03 | L26: 43814448 | M26: 793905 | O26: =($AB26-L26)/$AB26 -> 0.63567472 | P26: =($AI26-L26)/$AI26 -> 0.70695988 | Q26: =L26/M26 -> 55.188528 | S26: 1874.29 | T26: 45640047 | U26: 789693 | W26: =($AB26-T26)/$AB26 -> 0.62049453 | X26: =($AI26-T26)/$AI26 -> 0.69474989 | Y26: =T26/U26 -> 57.794671 | AA26: 4885.14 | AB26: 120261894 | AC26: 564092 | AE26: =($AI26-AB26)/$AI26 -> 0.1956635 | AF26: =AB26/AC26 -> 213.19553 | AH26: 45354.6 | AI26: 149516892 | AJ26: 492560 | AL26: =AI26/AJ26 -> 303.55062 | AT26: AVG | AU26: =AVERAGE(AU5:AU26) -> 2.8997056

Sheet Sheet2
A1: Net Optimized | B1: No Net Optimized | C1: No Net Opt/ Net Applied | D1: Edges | E1: Net Opt Success
A2: 7 | B2: 4 | C2: 6 | D2: 3 | E2: =A2/C2 -> 1.1666667
A3: 8 | B3: 4 | C3: 6 | D3: 4 | E3: =A3/C3 -> 1.3333333
A4: 9 | B4: 4 | C4: 8 | D4: 7 | E4: =A4/C4 -> 1.125
A5: 11 | B5: 4 | C5: 10 | D5: 10 | E5: =A5/C5 -> 1.1
A6: 13 | B6: 4 | C6: 10 | D6: 13 | E6: =A6/C6 -> 1.3
A7: 14 | B7: 4 | C7: 11 | D7: 15 | E7: =A7/C7 -> 1.2727273
A8: 14 | B8: 4 | C8: 11 | D8: 15 | E8: =A8/C8 -> 1.2727273
A9: 16 | B9: 4 | C9: 11 | D9: 18 | E9: =A9/C9 -> 1.4545455
A10: 16 | B10: 4 | C10: 12 | D10: 20 | E10: =A10/C10 -> 1.3333333
A11: 16 | B11: 4 | C11: 14 | D11: 22 | E11: =A11/C11 -> 1.1428571
A12: 19 | B12: 4 | C12: 16 | D12: 36 | E12: =A12/C12 -> 1.1875
A13: 20 | B13: 4 | C13: 19 | D13: 60 | E13: =A13/C13 -> 1.0526316
... A18: 20 | B18: 4 | C18: 20 | D18: 154 | E18: =A18/C18 -> 1

Sheet TestInstances
C5: Instance | D5: c | E5: u | F5: a
C6: 1 | D6: 2 | E6: 100 | F6: 0
C7: 2 | D7: 5 | E7: 100 | F7: 0
C8: 3 | D8: 5 | E8: 200 | F8: 0
C9: 4 | D9: 5 | E9: 500 | F9: 2
C10: 5 | D10: 5 | E10: 700 | F10: 4
C11: 6 | D11: 5 | E11: 1000 | F11: 12
C12: 7 | D12: 10 | E12: 1000 | F12: 12
C13: 8 | D13: 10 | E13: 2000 | F13: 56
C14: 9 | D14: 10 | E14: 3000 | F14: 122
C15: 10 | D15: 10 | E15: 4000 | F15: 244
C16: 11 | D16: 10 | E16: 5000 | F16: 392
C17: 12 | D17: 10 | E17: 10000 | F17: 1606
... C27: 22 | D27: 10 | E27: 60000 | F27: 53644
I29: Small | N29: Medium | S29: Large
I30: Instance | J30: c | K30: u | L30: a | N30: Instance | O30: c | P30: u | Q30: a | S30: Instance | T30: c | U30: u | V30: a
I31: 1 | J31: 1 | K31: 100 | L31: 0 | N31: 8 | O31: 10 | P31: 2000 | Q31: 56 | S31: 15 | T31: 10 | U31: 25000 | V31: 9472
I32: 2 | J32: 2 | K32: 100 | L32: 0 | N32: 9 | O32: 10 | P32: 3000 | Q32: 122 | S32: 16 | T32: 10 | U32: 30000 | V32: 13646
I33: 3 | J33: 5 | K33: 200 | L33: 0 | N33: 10 | O33: 10 | P33: 4000 | Q33: 244 | S33: 17 | T33: 10 | U33: 35000 | V33: 18388
I34: 4 | J34: 5 | K34: 500 | L34: 2 | N34: 11 | O34: 10 | P34: 5000 | Q34: 392 | S34: 18 | T34: 10 | U34: 40000 | V34: 23990
I35: 5 | J35: 5 | K35: 700 | L35: 4 | N35: 12 | O35: 10 | P35: 10000 | Q35: 1606 | S35: 19 | T35: 10 | U35: 45000 | V35: 30476
I36: 6 | J36: 5 | K36: 1000 | L36: 12 | N36: 13 | O36: 10 | P36: 15000 | Q36: 3548 | S36: 20 | T36: 10 | U36: 50000 | V36: 37502
I37: 7 | J37: 10 | K37: 1000 | L37: 12 | N37: 14 | O37: 10 | P37: 20000 | Q37: 6100 | S37: 21 | T37: 10 | U37: 55000 | V37: 44992

Sheet OV over DM
E8: Instance | F8: Exact (CPLEX Solver) | G8: Agg+ Grdy(A) | H8: Agg+Grdy(B) | I8: Agg+Grdy(B) | J8: SA+Agg+ Grdy©
E9: 1 | F9: 55.567 | G9: 55.712329 | H9: 55.712329 | I9: 55.712329 | J9: 55.684211
E10: 2 | F10: 28.588 | G10: 28.613861 | H10: 28.613861 | I10: 28.592233 | J10: 28.677686
E11: 3 | F11: 49.042 | G11: 49.091667 | H11: 49.100671 | I11: 49.037471 | J11: 49.087866
E12: 4 | F12: 24.075 | G12: 24.070796 | H12: 24.058104 | I12: 24.08686 | J12: 24.095698
E13: 5 | F13: 57.923 | G13: 57.913761 | H13: 57.899135 | I13: 57.921109 | J13: 57.940881
E14: 6 | F14: 13.792 | G14: 13.794279 | H14: 13.794404 | I14: 13.790481 | J14: 13.79273
E15: 7 | F15: 23.728 | G15: 23.733699 | H15: 23.732669 | I15: 23.725195 | J15: 23.729269
E16: 8 | F16: 39.391 | G16: 29.075956 | H16: 29.475831 | I16: 30.750466 | J16: 39.393946
E17: 9 | F17: 59.155 | G17: 28.165759 | H17: 28.447929 | I17: 50.199273 | J17: 59.157081
E18: 10 | F18: 52.597 | G18: 35.759176 | H18: 35.733568 | I18: 45.977727 | J18: 52.598314
E19: 11 | F19: 50.421 | G19: 30.797938 | H19: 30.763817 | I19: 47.328412 | J19: 50.422025
E20: 12 | F20: 88.591 | G20: 33.487172 | H20: 34.783334 | I20: 49.642445 | J20: 88.592837
... E23: 15 | F23: 116.88 | G23: 47.540738 | H23: 48.048843 | I23: 80.698586 | J23: 116.87897
E24: 16 | F24: - | G24: 48.321011 | H24: 50.65483 | I24: 83.7503 | J24: 103.56101
E25: 17 | F25: - | G25: 50.388227 | H25: 52.737449 | I25: 98.947926 | J25: 132.85318
E26: 18 | F26: - | G26: 54.697256 | H26: 56.062744 | I26: 139.03428 | J26: 181.5724
E27: 19 | F27: - | G27: 60.308204 | H27: 58.439418 | I27: 217.36386 | J27: 282.84033
E28: 20 | F28: - | G28: 58.332861 | H28: 58.760919 | I28: 267.3503 | J28: 272.97635
E29: 21 | F29: - | G29: 57.050883 | H29: 58.243245 | I29: 206.95177 | J29: 291.45039
E30: 22 | F30: - | G30: 55.188528 | H30: 57.794671 | I30: 213.19553 | J30: 303.55062

Sheet OvGap
A2: Instance | B2: Objective Value Gap (%) | F2: Time (sec) | L2: Instance | M2: Objective Value Gap (%) | R2: Time (sec)
B3: A+G Algorithm-A | C3: A+G Algorithm-B | D3: A+G Algorithm-C | F3: Exact(BIP) | G3: A+G Algorithm-A | H3: A+G Algorithm-B | I3: A+G Algorithm-C | M3: Agg+Grdy Alg-A | N3: Agg+Grdy Alg-B | O3: Agg+Grdy Alg-C | P3: SimA+Grdy Alg-C | R3: Exact(BIP) | S3: Agg+Grdy Alg-A | T3: Agg+Grdy Alg-B | U3: Agg+Grdy Alg-C | V3: SimA+Grdy Alg-C
A4: 1 | B4: =NetworkingLESS!N5 -> 0.24545455 | C4: =NetworkingLESS!V5 -> 0.24545455 | D4: =NetworkingLESS!AD5 -> 0.24545455 | F4: =NetworkingLESS!E5 -> 0.02 | G4: =NetworkingLESS!K5 -> 0 | H4: =NetworkingLESS!S5 -> 0 | I4: =NetworkingLESS!AA5 -> 0.03 | L4: 1 | M4: =NetworkingLESS!N5 -> 0.24545455 | N4: =NetworkingLESS!V5 -> 0.24545455 | O4: =NetworkingLESS!AD5 -> 0.24545455 | P4: =NetworkingLESS!AK4 -> 0 | R4: =NetworkingLESS!E5 -> 0.02 | S4: =NetworkingLESS!K5 -> 0 | T4: =NetworkingLESS!S5 -> 0 | U4: =NetworkingLESS!AA5 -> 0.03 | V4: =NetworkingLESS!AH5 -> 3.4
A5: 2 | B5: =NetworkingLESS!N6 -> 0.60356653 | C5: =NetworkingLESS!V6 -> 0.60356653 | D5: =NetworkingLESS!AD6 -> 0.1920439 | F5: =NetworkingLESS!E6 -> 0.07 | G5: =NetworkingLESS!K6 -> 0 | H5: =NetworkingLESS!S6 -> 0 | I5: =NetworkingLESS!AA6 -> 0.06 | L5: 2 | M5: =NetworkingLESS!N6 -> 0.60356653 | N5: =NetworkingLESS!V6 -> 0.60356653 | O5: =NetworkingLESS!AD6 -> 0.1920439 | P5: =NetworkingLESS!AK5 -> 0.018552876 | R5: =NetworkingLESS!E6 -> 0.07 | S5: =NetworkingLESS!K6 -> 0 | T5: =NetworkingLESS!S6 -> 0 | U5: =NetworkingLESS!AA6 -> 0.06 | V5: =NetworkingLESS!AH6 -> 3.65
A6: 3 | B6: =NetworkingLESS!N7 -> 0.51855181 | C6: =NetworkingLESS!V7 -> 0.40209219 | D6: =NetworkingLESS!AD7 -> 0.14436907 | F6: =NetworkingLESS!E7 -> 0.1 | G6: =NetworkingLESS!K7 -> 0 | H6: =NetworkingLESS!S7 -> 0 | I6: =NetworkingLESS!AA7 -> 0.1 | L6: 3 | M6: =NetworkingLESS!N7 -> 0.51855181 | N6: =NetworkingLESS!V7 -> 0.40209219 | O6: =NetworkingLESS!AD7 -> 0.14436907 | P6: =NetworkingLESS!AK6 -> 0.048010974 | R6: =NetworkingLESS!E7 -> 0.1 | S6: =NetworkingLESS!K7 -> 0 | T6: =NetworkingLESS!S7 -> 0 | U6: =NetworkingLESS!AA7 -> 0.1 | V6: =NetworkingLESS!AH7 -> 3.85
A7: 4 | B7: =NetworkingLESS!N8 -> 0.62927627 | C7: =NetworkingLESS!V8 -> 0.4638817 | D7: =NetworkingLESS!AD8 -> 0.26298215 | F7: =NetworkingLESS!E8 -> 0.27 | G7: =NetworkingLESS!K8 -> 0.02 | H7: =NetworkingLESS!S8 -> 0.05 | I7: =NetworkingLESS!AA8 -> 0.33 | L7: 4 | M7: =NetworkingLESS!N8 -> 0.62927627 | N7: =NetworkingLESS!V8 -> 0.4638817 | O7: =NetworkingLESS!AD8 -> 0.26298215 | P7: =NetworkingLESS!AK7 -> 0.041189931 | R7: =NetworkingLESS!E8 -> 0.27 | S7: =NetworkingLESS!K8 -> 0.02 | T7: =NetworkingLESS!S8 -> 0.05 | U7: =NetworkingLESS!AA8 -> 0.33 | V7: =NetworkingLESS!AH8 -> 4.95
A8: 5 | B8: =NetworkingLESS!N9 -> 0.68208098 | C8: =NetworkingLESS!V9 -> 0.59526591 | D8: =NetworkingLESS!AD9 -> 0.17913981 | F8: =NetworkingLESS!E9 -> 0.41 | G8: =NetworkingLESS!K9 -> 0.05 | H8: =NetworkingLESS!S9 -> 0.09 | I8: =NetworkingLESS!AA9 -> 0.57 | L8: 5 | M8: =NetworkingLESS!N9 -> 0.68208098 | N8: =NetworkingLESS!V9 -> 0.59526591 | O8: =NetworkingLESS!AD9 -> 0.17913981 | P8: =NetworkingLESS!AK8 -> 0.064842579 | R8: =NetworkingLESS!E9 -> 0.41 | S8: =NetworkingLESS!K9 -> 0.05 | T8: =NetworkingLESS!S9 -> 0.09 | U8: =NetworkingLESS!AA9 -> 0.57 | V8: =NetworkingLESS!AH9 -> 5.4
A9: 6 | B9: =NetworkingLESS!N10 -> 0.31385668 | C9: =NetworkingLESS!V10 -> 0.31343284 | D9: =NetworkingLESS!AD10 -> 0.19297024 | F9: =NetworkingLESS!E10 -> 0.63 | G9: =NetworkingLESS!K10 -> 0.1 | H9: =NetworkingLESS!S10 -> 0.19 | I9: =NetworkingLESS!AA10 -> 1.1 | L9: 6 | M9: =NetworkingLESS!N10 -> 0.31385668 | N9: =NetworkingLESS!V10 -> 0.31343284 | O9: =NetworkingLESS!AD10 -> 0.19297024 | P9: =NetworkingLESS!AK9 -> 0.072058824 | R9: =NetworkingLESS!E10 -> 0.63 | S9: =NetworkingLESS!K10 -> 0.1 | T9: =NetworkingLESS!S10 -> 0.19 | U9: =NetworkingLESS!AA10 -> 1.1 | V9: =NetworkingLESS!AH10 -> 10.15
A10: 7 | B10: =NetworkingLESS!N11 -> 0.70056199 | C10: =NetworkingLESS!V11 -> 0.52568776 | D10: =NetworkingLESS!AD11 -> 0.1821307 | F10: =NetworkingLESS!E11 -> 1.29 | G10: =NetworkingLESS!K11 -> 0.15 | H10: =NetworkingLESS!S11 -> 0.24 | I10: =NetworkingLESS!AA11 -> 2.24 | L10: 7 | M10: =NetworkingLESS!N11 -> 0.70056199 | N10: =NetworkingLESS!V11 -> 0.52568776 | O10: =NetworkingLESS!AD11 -> 0.1821307 | P10: =NetworkingLESS!AK10 -> 0.034997427 | R10: =NetworkingLESS!E11 -> 1.29 | S10: =NetworkingLESS!K11 -> 0.15 | T10: =NetworkingLESS!S11 -> 0.24 | U10: =NetworkingLESS!AA11 -> 2.24 | V10: =NetworkingLESS!AH11 -> 21.8
A11: 8 | B11: =NetworkingLESS!N12 -> 0.70038217 | C11: =NetworkingLESS!V12 -> 0.68401023 | D11: =NetworkingLESS!AD12 -> 0.24333895 | F11: =NetworkingLESS!E12 -> 4.26 | G11: =NetworkingLESS!K12 -> 0.6 | H11: =NetworkingLESS!S12 -> 0.97 | I11: =NetworkingLESS!AA12 -> 8.75 | L11: 8 | M11: =NetworkingLESS!N12 -> 0.70038217 | N11: =NetworkingLESS!V12 -> 0.68401023 | O11: =NetworkingLESS!AD12 -> 0.24333895 | P11: =NetworkingLESS!AK11 -> 0.083155096 | R11: =NetworkingLESS!E12 -> 4.26 | S11: =NetworkingLESS!K12 -> 0.6 | T11: =NetworkingLESS!S12 -> 0.97 | U11: =NetworkingLESS!AA12 -> 8.75 | V11: =NetworkingLESS!AH12 -> 79.1
A12: 9 | B12: =NetworkingLESS!N13 -> 0.66356532 | C12: =NetworkingLESS!V13 -> 0.66393328 | D12: =NetworkingLESS!AD13 -> 0.17018102 | F12: =NetworkingLESS!E13 -> 11.3 | G12: =NetworkingLESS!K13 -> 1.36 | H12: =NetworkingLESS!S13 -> 2.18 | I12: =NetworkingLESS!AA13 -> 20.1 | L12: 9 | M12: =NetworkingLESS!N13 -> 0.66356532 | N12: =NetworkingLESS!V13 -> 0.66393328 | O12: =NetworkingLESS!AD13 -> 0.17018102 | P12: =NetworkingLESS!AK12 -> 0.051598869 | R12: =NetworkingLESS!E13 -> 11.3 | S12: =NetworkingLESS!K13 -> 1.36 | T12: =NetworkingLESS!S13 -> 2.18 | U12: =NetworkingLESS!AA13 -> 20.1 | V12: =NetworkingLESS!AH13 -> 189.75
A13: 10 | B13: =NetworkingLESS!N14 -> 0.63726799 | C13: =NetworkingLESS!V14 -> 0.63810789 | D13: =NetworkingLESS!AD14 -> 0.20905404 | F13: =NetworkingLESS!E14 -> 24.03 | G13: =NetworkingLESS!K14 -> 2.43 | H13: =NetworkingLESS!S14 -> 3.88 | I13: =NetworkingLESS!AA14 -> 37.33 | L13: 10 | M13: =NetworkingLESS!N14 -> 0.63726799 | N13: =NetworkingLESS!V14 -> 0.63810789 | O13: =NetworkingLESS!AD14 -> 0.20905404 | P13: =NetworkingLESS!AK13 -> 0.075707627 | R13: =NetworkingLESS!E14 -> 24.03 | S13: =NetworkingLESS!K14 -> 2.43 | T13: =NetworkingLESS!S14 -> 3.88 | U13: =NetworkingLESS!AA14 -> 37.33 | V13: =NetworkingLESS!AH14 -> 331.75
A14: 11 | B14: =NetworkingLESS!N15 -> 0.70677433 | C14: =NetworkingLESS!V15 -> 0.70766909 | D14: =NetworkingLESS!AD15 -> 0.15677475 | F14: =NetworkingLESS!E15 -> 43.93 | G14: =NetworkingLESS!K15 -> 3.8 | H14: =NetworkingLESS!S15 -> 6.13 | I14: =NetworkingLESS!AA15 -> 60.39 | L14: 11 | M14: =NetworkingLESS!N15 -> 0.70677433 | N14: =NetworkingLESS!V15 -> 0.70766909 | O14: =NetworkingLESS!AD15 -> 0.15677475 | P14: =NetworkingLESS!AK14 -> 0.05439979 | R14: =NetworkingLESS!E15 -> 43.93 | S14: =NetworkingLESS!K15 -> 3.8 | T14: =NetworkingLESS!S15 -> 6.13 | U14: =NetworkingLESS!AA15 -> 60.39 | V14: =NetworkingLESS!AH15 -> 541.7
A15: 12 | B15: =NetworkingLESS!N16 -> 0.75607481 | C15: =NetworkingLESS!V16 -> 0.75674874 | D15: =NetworkingLESS!AD16 -> 0.20066238 | F15: =NetworkingLESS!E16 -> 309.96 | G15: =NetworkingLESS!K16 -> 15.53 | H15: =NetworkingLESS!S16 -> 25.1 | I15: =NetworkingLESS!AA16 -> 290.14 | L15: 12 | M15: =NetworkingLESS!N16 -> 0.75607481 | N15: =NetworkingLESS!V16 -> 0.75674874 | O15: =NetworkingLESS!AD16 -> 0.20066238 | P15: =NetworkingLESS!AK15 -> 0.028799975 | R15: =NetworkingLESS!E16 -> 309.96 | S15: =NetworkingLESS!K16 -> 15.53 | T15: =NetworkingLESS!S16 -> 25.1 | U15: =NetworkingLESS!AA16 -> 290.14 | V15: =NetworkingLESS!AH16 -> 2601.55
... A18: 15 | B18: =NetworkingLESS!N19 -> 0.68917969 | C18: =NetworkingLESS!V19 -> 0.68987194 | D18: =NetworkingLESS!AD19 -> 0.1910857 | F18: =NetworkingLESS!E19 -> 50792.01 | G18: =NetworkingLESS!K19 -> 109.15 | H18: =NetworkingLESS!S19 -> 168.04 | I18: =NetworkingLESS!AA19 -> 1668.64 | L18: 15 | M18: =NetworkingLESS!N19 -> 0.68917969 | N18: =NetworkingLESS!V19 -> 0.68987194 | O18: =NetworkingLESS!AD19 -> 0.1910857 | P18: =NetworkingLESS!AK18 -> 0.047400012 | R18: =NetworkingLESS!E19 -> 50792.01 | S18: =NetworkingLESS!K19 -> 109.15 | T18: =NetworkingLESS!S19 -> 168.04 | U18: =NetworkingLESS!AA19 -> 1668.64 | V18: =NetworkingLESS!AH19 -> 14829.85
A19: Average | B19: =AVERAGE(B4:B18) -> 0.62315535 | C19: =AVERAGE(C4:C18) -> 0.58555826 | D19: =AVERAGE(D4:D18) -> 0.20485566 | F19: =AVERAGE(F4:F18) -> 4143.7007 | G19: =AVERAGE(G4:G18) -> 15.685333 | H19: =AVERAGE(H4:H18) -> 24.616 | I19: =AVERAGE(I4:I18) -> 269.904 | L19: Average | M19: =AVERAGE(M4:M18) -> 0.62315535 | N19: =AVERAGE(N4:N18) -> 0.58555826 | O19: =AVERAGE(O4:O18) -> 0.20485566 | P19: =AVERAGE(P4:P18) -> 0.050462309 | R19: =AVERAGE(R4:R18) -> 4143.7007 | S19: =AVERAGE(S4:S18) -> 15.685333 | T19: =AVERAGE(T4:T18) -> 24.616 | U19: =AVERAGE(U4:U18) -> 269.904 | V19: =AVERAGE(V4:V18) -> 2467.86
A26: Instance | B26: Objective Value Gap (%) | F26: Time (sec)
B27: A+G Algorithm-A | C27: A+G Algorithm-B | D27: A+G Algorithm-C | F27: Exact(BIP) | G27: A+G Algorithm-A | H27: A+G Algorithm-B | I27: A+G Algorithm-C
A28: 1 | B28: =NetworkingLESS!N5 -> 0.24545455 | C28: =NetworkingLESS!V5 -> 0.24545455 | D28: =NetworkingLESS!AD5 -> 0.24545455 | F28: =NetworkingLESS!E5 -> 0.02 | G28: =NetworkingLESS!K5 -> 0 | H28: =NetworkingLESS!S5 -> 0 | I28: =NetworkingLESS!AA5 -> 0.03
A29: 2 | B29: =NetworkingLESS!N6 -> 0.60356653 | C29: =NetworkingLESS!V6 -> 0.60356653 | D29: =NetworkingLESS!AD6 -> 0.1920439 | F29: =NetworkingLESS!E6 -> 0.07 | G29: =NetworkingLESS!K6 -> 0 | H29: =NetworkingLESS!S6 -> 0 | I29: =NetworkingLESS!AA6 -> 0.06
A30: 3 | B30: =NetworkingLESS!N7 -> 0.51855181 | C30: =NetworkingLESS!V7 -> 0.40209219 | D30: =NetworkingLESS!AD7 -> 0.14436907 | F30: =NetworkingLESS!E7 -> 0.1 | G30: =NetworkingLESS!K7 -> 0 | H30: =NetworkingLESS!S7 -> 0 | I30: =NetworkingLESS!AA7 -> 0.1
A31: 4 | B31: =NetworkingLESS!N8 -> 0.62927627 | C31: =NetworkingLESS!V8 -> 0.4638817 | D31: =NetworkingLESS!AD8 -> 0.26298215 | F31: =NetworkingLESS!E8 -> 0.27 | G31: =NetworkingLESS!K8 -> 0.02 | H31: =NetworkingLESS!S8 -> 0.05 | I31: =NetworkingLESS!AA8 -> 0.33
A32: 5 | B32: =NetworkingLESS!N9 -> 0.68208098 | C32: =NetworkingLESS!V9 -> 0.59526591 | D32: =NetworkingLESS!AD9 -> 0.17913981 | F32: =NetworkingLESS!E9 -> 0.41 | G32: =NetworkingLESS!K9 -> 0.05 | H32: =NetworkingLESS!S9 -> 0.09 | I32: =NetworkingLESS!AA9 -> 0.57
A33: 6 | B33: =NetworkingLESS!N10 -> 0.31385668 | C33: =NetworkingLESS!V10 -> 0.31343284 | D33: =NetworkingLESS!AD10 -> 0.19297024 | F33: =NetworkingLESS!E10 -> 0.63 | G33: =NetworkingLESS!K10 -> 0.1 | H33: =NetworkingLESS!S10 -> 0.19 | I33: =NetworkingLESS!AA10 -> 1.1
A34: 7 | B34: =NetworkingLESS!N11 -> 0.70056199 | C34: =NetworkingLESS!V11 -> 0.52568776 | D34: =NetworkingLESS!AD11 -> 0.1821307 | F34: =NetworkingLESS!E11 -> 1.29 | G34: =NetworkingLESS!K11 -> 0.15 | H34: =NetworkingLESS!S11 -> 0.24 | I34: =NetworkingLESS!AA11 -> 2.24
A35: 8 | B35: =NetworkingLESS!N12 -> 0.70038217 | C35: =NetworkingLESS!V12 -> 0.68401023 | D35: =NetworkingLESS!AD12 -> 0.24333895 | F35: =NetworkingLESS!E12 -> 4.26 | G35: =NetworkingLESS!K12 -> 0.6 | H35: =NetworkingLESS!S12 -> 0.97 | I35: =NetworkingLESS!AA12 -> 8.75
A36: 9 | B36: =NetworkingLESS!N13 -> 0.66356532 | C36: =NetworkingLESS!V13 -> 0.66393328 | D36: =NetworkingLESS!AD13 -> 0.17018102 | F36: =NetworkingLESS!E13 -> 11.3 | G36: =NetworkingLESS!K13 -> 1.36 | H36: =NetworkingLESS!S13 -> 2.18 | I36: =NetworkingLESS!AA13 -> 20.1
A37: 10 | B37: =NetworkingLESS!N14 -> 0.63726799 | C37: =NetworkingLESS!V14 -> 0.63810789 | D37: =NetworkingLESS!AD14 -> 0.20905404 | F37: =NetworkingLESS!E14 -> 24.03 | G37: =NetworkingLESS!K14 -> 2.43 | H37: =NetworkingLESS!S14 -> 3.88 | I37: =NetworkingLESS!AA14 -> 37.33
A38: 11 | B38: =NetworkingLESS!N15 -> 0.70677433 | C38: =NetworkingLESS!V15 -> 0.70766909 | D38: =NetworkingLESS!AD15 -> 0.15677475 | F38: =NetworkingLESS!E15 -> 43.93 | G38: =NetworkingLESS!K15 -> 3.8 | H38: =NetworkingLESS!S15 -> 6.13 | I38: =NetworkingLESS!AA15 -> 60.39
A39: 12 | B39: =NetworkingLESS!N16 -> 0.75607481 | C39: =NetworkingLESS!V16 -> 0.75674874 | D39: =NetworkingLESS!AD16 -> 0.20066238 | F39: =NetworkingLESS!E16 -> 309.96 | G39: =NetworkingLESS!K16 -> 15.53 | H39: =NetworkingLESS!S16 -> 25.1 | I39: =NetworkingLESS!AA16 -> 290.14
... A42: 15 | B42: =NetworkingLESS!N19 -> 0.68917969 | C42: =NetworkingLESS!V19 -> 0.68987194 | D42: =NetworkingLESS!AD19 -> 0.1910857 | F42: =NetworkingLESS!E19 -> 50792.01 | G42: =NetworkingLESS!K19 -> 109.15 | H42: =NetworkingLESS!S19 -> 168.04 | I42: =NetworkingLESS!AA19 -> 1668.64
A43: Average | B43: =AVERAGE(B28:B42) -> 0.62315535 | C43: =AVERAGE(C28:C42) -> 0.58555826 | D43: =AVERAGE(D28:D42) -> 0.20485566 | F43: =AVERAGE(F28:F42) -> 4143.7007 | G43: =AVERAGE(G28:G42) -> 15.685333 | H43: =AVERAGE(H28:H42) -> 24.616 | I43: =AVERAGE(I28:I42) -> 269.904

Sheet IntraGap
A2: Instance | B2: Objective Value Gap To Algorithm-C(%) | E2: Time (sec) | I2: Instance | J2: Obj. Value Gap To SimAnn+Grdy Alg-C(\%) | N2: Time (sec)
B3: A+G Algorithm-A | C3: A+G Algorithm-B | E3: A+G Algorithm-A | F3: A+G Algorithm-B | G3: A+G Algorithm-C | J3: Agg+Grdy Alg-A | K3: Agg+Grdy Alg-B | L3: Agg+Grdy Alg-C | N3: Agg+Grdy Alg-A | O3: Agg+Grdy Alg-B | P3: Agg+Grdy Alg-C | Q3: SimAnn+Grdy Alg-C
A4: 1 | B4: =NetworkingLESS!O5 -> 0 | C4: =NetworkingLESS!W5 -> 0 | E4: =NetworkingLESS!K5 -> 0 | F4: =NetworkingLESS!S5 -> 0 | G4: =NetworkingLESS!AA5 -> 0.03 | I4: 1 | J4: =NetworkingLESS!P5 -> 0.23119093 | K4: =NetworkingLESS!X5 -> 0.23119093 | L4: =NetworkingLESS!AE4 -> 0 | N4: =NetworkingLESS!K5 -> 0 | O4: =NetworkingLESS!S5 -> 0 | P4: =NetworkingLESS!AA5 -> 0.03 | Q4: =NetworkingLESS!AH5 -> 3.4
A5: 2 | B5: =NetworkingLESS!O6 -> 0.50933786 | C5: =NetworkingLESS!W6 -> 0.50933786 | E5: =NetworkingLESS!K6 -> 0 | F5: =NetworkingLESS!S6 -> 0 | G5: =NetworkingLESS!AA6 -> 0.06 | I5: 2 | J5: =NetworkingLESS!P6 -> 0.58357349 | K5: =NetworkingLESS!X6 -> 0.58357349 | L5: =NetworkingLESS!AE5 -> 0.23119093 | N5: =NetworkingLESS!K6 -> 0 | O5: =NetworkingLESS!S6 -> 0 | P5: =NetworkingLESS!AA6 -> 0.06 | Q5: =NetworkingLESS!AH6 -> 3.65
A6: 3 | B6: =NetworkingLESS!O7 -> 0.43731792 | C6: =NetworkingLESS!W7 -> 0.30120827 | E6: =NetworkingLESS!K7 -> 0 | F6: =NetworkingLESS!S7 -> 0 | G6: =NetworkingLESS!AA7 -> 0.1 | I6: 3 | J6: =NetworkingLESS!P7 -> 0.49786908 | K6: =NetworkingLESS!X7 -> 0.37640641 | L6: =NetworkingLESS!AE6 -> 0.15129683 | N6: =NetworkingLESS!K7 -> 0 | O6: =NetworkingLESS!S7 -> 0 | P6: =NetworkingLESS!AA7 -> 0.1 | Q6: =NetworkingLESS!AH7 -> 3.85
A7: 4 | B7: =NetworkingLESS!O8 -> 0.49699491 | C7: =NetworkingLESS!W8 -> 0.27258437 | E7: =NetworkingLESS!K8 -> 0.02 | F7: =NetworkingLESS!S8 -> 0.05 | G7: =NetworkingLESS!AA8 -> 0.33 | I7: 4 | J7: =NetworkingLESS!P8 -> 0.60357078 | K7: =NetworkingLESS!X8 -> 0.42670796 | L7: =NetworkingLESS!AE7 -> 0.10761166 | N7: =NetworkingLESS!K8 -> 0.02 | O7: =NetworkingLESS!S8 -> 0.05 | P7: =NetworkingLESS!AA8 -> 0.33 | Q7: =NetworkingLESS!AH8 -> 4.95
A8: 5 | B8: =NetworkingLESS!O9 -> 0.61270017 | C8: =NetworkingLESS!W9 -> 0.50693908 | E8: =NetworkingLESS!K9 -> 0.05 | F8: =NetworkingLESS!S9 -> 0.09 | G8: =NetworkingLESS!AA9 -> 0.57 | I8: 5 | J8: =NetworkingLESS!P9 -> 0.65739314 | K8: =NetworkingLESS!X9 -> 0.56383648 | L8: =NetworkingLESS!AE8 -> 0.2118783 | N8: =NetworkingLESS!K9 -> 0.05 | O8: =NetworkingLESS!S9 -> 0.09 | P8: =NetworkingLESS!AA9 -> 0.57 | Q8: =NetworkingLESS!AH9 -> 5.4
A9: 6 | B9: =NetworkingLESS!O10 -> 0.1497918 | C9: =NetworkingLESS!W10 -> 0.14926661 | E9: =NetworkingLESS!K10 -> 0.1 | F9: =NetworkingLESS!S10 -> 0.19 | G9: =NetworkingLESS!AA10 -> 1.1 | I9: 6 | J9: =NetworkingLESS!P10 -> 0.28897255 | K9: =NetworkingLESS!X10 -> 0.28853333 | L9: =NetworkingLESS!AE9 -> 0.11539631 | N9: =NetworkingLESS!K10 -> 0.1 | O9: =NetworkingLESS!S10 -> 0.19 | P9: =NetworkingLESS!AA10 -> 1.1 | Q9: =NetworkingLESS!AH10 -> 10.15
A10: 7 | B10: =NetworkingLESS!O11 -> 0.63388036 | C10: =NetworkingLESS!W11 -> 0.42006353 | E10: =NetworkingLESS!K11 -> 0.15 | F10: =NetworkingLESS!S11 -> 0.24 | G10: =NetworkingLESS!AA11 -> 2.24 | I10: 7 | J10: =NetworkingLESS!P11 -> 0.67340385 | K10: =NetworkingLESS!X11 -> 0.48266906 | L10: =NetworkingLESS!AE10 -> 0.16370196 | N10: =NetworkingLESS!K11 -> 0.15 | O10: =NetworkingLESS!S11 -> 0.24 | P10: =NetworkingLESS!AA11 -> 2.24 | Q10: =NetworkingLESS!AH11 -> 21.8
A11: 8 | B11: =NetworkingLESS!O12 -> 0.60402637 | C11: =NetworkingLESS!W12 -> 0.58238928 | E11: =NetworkingLESS!K12 -> 0.6 | F11: =NetworkingLESS!S12 -> 0.97 | G11: =NetworkingLESS!AA12 -> 8.75 | I11: 8 | J11: =NetworkingLESS!P12 -> 0.68408112 | K11: =NetworkingLESS!X12 -> 0.66681844 | L11: =NetworkingLESS!AE11 -> 0.1079524 | N11: =NetworkingLESS!K12 -> 0.6 | O11: =NetworkingLESS!S12 -> 0.97 | P11: =NetworkingLESS!AA12 -> 8.75 | Q11: =NetworkingLESS!AH12 -> 79.1
A12: 9 | B12: =NetworkingLESS!O13 -> 0.59456859 | C12: =NetworkingLESS!W13 -> 0.59501201 | E12: =NetworkingLESS!K13 -> 1.36 | F12: =NetworkingLESS!S13 -> 2.18 | G12: =NetworkingLESS!AA13 -> 20.1 | I12: 9 | J12: =NetworkingLESS!P13 -> 0.63600838 | K12: =NetworkingLESS!X13 -> 0.63640647 | L12: =NetworkingLESS!AE12 -> 0.20217192 | N12: =NetworkingLESS!K13 -> 1.36 | O12: =NetworkingLESS!S13 -> 2.18 | P12: =NetworkingLESS!AA13 -> 20.1 | Q12: =NetworkingLESS!AH13 -> 189.75
A13: 10 | B13: =NetworkingLESS!O14 -> 0.54139469 | C13: =NetworkingLESS!W14 -> 0.54245659 | E13: =NetworkingLESS!K14 -> 2.43 | F13: =NetworkingLESS!S14 -> 3.88 | G13: =NetworkingLESS!AA14 -> 37.33 | I13: 10 | J13: =NetworkingLESS!P14 -> 0.61640024 | K13: =NetworkingLESS!X14 -> 0.61728846 | L13: =NetworkingLESS!AE13 -> 0.10221159 | N13: =NetworkingLESS!K14 -> 2.43 | O13: =NetworkingLESS!S14 -> 3.88 | P13: =NetworkingLESS!AA14 -> 37.33 | Q13: =NetworkingLESS!AH14 -> 331.75
A14: 11 | B14: =NetworkingLESS!O15 -> 0.65225701 | C14: =NetworkingLESS!W15 -> 0.65331813 | E14: =NetworkingLESS!K15 -> 3.8 | F14: =NetworkingLESS!S15 -> 6.13 | G14: =NetworkingLESS!AA15 -> 60.39 | I14: 11 | J14: =NetworkingLESS!P15 -> 0.69807902 | K14: =NetworkingLESS!X15 -> 0.69900031 | L14: =NetworkingLESS!AE14 -> 0.16355141 | N14: =NetworkingLESS!K15 -> 3.8 | O14: =NetworkingLESS!S15 -> 6.13 | P14: =NetworkingLESS!AA15 -> 60.39 | Q14: =NetworkingLESS!AH15 -> 541.7
A15: 12 | B15: =NetworkingLESS!O16 -> 0.69484085 | C15: =NetworkingLESS!W16 -> 0.69568396 | E15: =NetworkingLESS!K16 -> 15.53 | F15: =NetworkingLESS!S16 -> 25.1 | G15: =NetworkingLESS!AA16 -> 290.14 | I15: 12 | J15: =NetworkingLESS!P16 -> 0.74543396 | K15: =NetworkingLESS!X16 -> 0.74613729 | L15: =NetworkingLESS!AE15 -> 0.13176974 | N15: =NetworkingLESS!K16 -> 15.53 | O15: =NetworkingLESS!S16 -> 25.1 | P15: =NetworkingLESS!AA16 -> 290.14 | Q15: =NetworkingLESS!AH16 -> 2601.55
... A18: 15 | B18: =NetworkingLESS!O19 -> 0.61575619 | C18: =NetworkingLESS!W19 -> 0.61661197 | E18: =NetworkingLESS!K19 -> 109.15 | F18: =NetworkingLESS!S19 -> 168.04 | G18: =NetworkingLESS!AA19 -> 1668.64 | I18: 15 | J18: =NetworkingLESS!P19 -> 0.6704769 | K18: =NetworkingLESS!X19 -> 0.67121081 | L18: =NetworkingLESS!AE18 -> 0.22651716 | N18: =NetworkingLESS!K19 -> 109.15 | O18: =NetworkingLESS!S19 -> 168.04 | P18: =NetworkingLESS!AA19 -> 1668.64 | Q18: =NetworkingLESS!AH19 -> 14829.85
A19: Average | B19: =AVERAGE(B4:B18) -> 0.52510754 | C19: =AVERAGE(C4:C18) -> 0.47793047 | E19: =AVERAGE(E4:E18) -> 15.685333 | F19: =AVERAGE(F4:F18) -> 24.616 | G19: =AVERAGE(G4:G18) -> 269.904 | I19: Average | J19: =AVERAGE(J4:J18) -> 0.6031829 | K19: =AVERAGE(K4:K18) -> 0.56291254 | L19: =AVERAGE(L4:L18) -> 0.14941419 | N19: =AVERAGE(N4:N18) -> 15.685333 | O19: =AVERAGE(O4:O18) -> 24.616 | P19: =AVERAGE(P4:P18) -> 269.904 | Q19: =AVERAGE(Q4:Q18) -> 2467.86
A20: 16 | B20: =NetworkingLESS!O20 -> 0.52836155 | C20: =NetworkingLESS!W20 -> 0.50870988 | E20: =NetworkingLESS!K20 -> 163.15 | F20: =NetworkingLESS!S20 -> 253.59 | G20: =NetworkingLESS!AA20 -> 2128.14 | I20: 16 | J20: =NetworkingLESS!P20 -> 0.60366518 | K20: =NetworkingLESS!X20 -> 0.58715117 | L20: =NetworkingLESS!AE20 -> 0.15966389 | N20: =NetworkingLESS!K20 -> 163.15 | O20: =NetworkingLESS!S20 -> 253.59 | P20: =NetworkingLESS!AA20 -> 2128.14 | Q20: =NetworkingLESS!AH20 -> 18913.65
A21: 17 | B21: =NetworkingLESS!O21 -> 0.57507991 | C21: =NetworkingLESS!W21 -> 0.55737481 | E21: =NetworkingLESS!K21 -> 231.98 | F21: =NetworkingLESS!S21 -> 357.76 | G21: =NetworkingLESS!AA21 -> 2587.64 | I21: 17 | J21: =NetworkingLESS!P21 -> 0.65453651 | K21: =NetworkingLESS!X21 -> 0.64014212 | L21: =NetworkingLESS!AE21 -> 0.18699188 | N21: =NetworkingLESS!K21 -> 231.98 | O21: =NetworkingLESS!S21 -> 357.76 | P21: =NetworkingLESS!AA21 -> 2587.64 | Q21: =NetworkingLESS!AH21 -> 25256.1
A22: 18 | B22: =NetworkingLESS!O22 -> 0.57020981 | C22: =NetworkingLESS!W22 -> 0.55230189 | E22: =NetworkingLESS!K22 -> 316.46 | F22: =NetworkingLESS!S22 -> 496.71 | G22: =NetworkingLESS!AA22 -> 3047.14 | I22: 18 | J22: =NetworkingLESS!P22 -> 0.66752256 | K22: =NetworkingLESS!X22 -> 0.65366933 | L22: =NetworkingLESS!AE22 -> 0.22641918 | N22: =NetworkingLESS!K22 -> 316.46 | O22: =NetworkingLESS!S22 -> 496.71 | P22: =NetworkingLESS!AA22 -> 3047.14 | Q22: =NetworkingLESS!AH22 -> 28532.15
A23: 19 | B23: =NetworkingLESS!O23 -> 0.60378256 | C23: =NetworkingLESS!W23 -> 0.43100748 | E23: =NetworkingLESS!K23 -> 415.75 | F23: =NetworkingLESS!S23 -> 653.14 | G23: =NetworkingLESS!AA23 -> 3506.64 | I23: 19 | J23: =NetworkingLESS!P23 -> 0.67254757 | K23: =NetworkingLESS!X23 -> 0.52975825 | L23: =NetworkingLESS!AE23 -> 0.17355372 | N23: =NetworkingLESS!K23 -> 415.75 | O23: =NetworkingLESS!S23 -> 653.14 | P23: =NetworkingLESS!AA23 -> 3506.64 | Q23: =NetworkingLESS!AH23 -> 33112.9
A24: 20 | B24: =NetworkingLESS!O24 -> 0.61083767 | C24: =NetworkingLESS!W24 -> 0.59462255 | E24: =NetworkingLESS!K24 -> 530.86 | F24: =NetworkingLESS!S24 -> 860.19 | G24: =NetworkingLESS!AA24 -> 3966.14 | I24: 20 | J24: =NetworkingLESS!P24 -> 0.67424732 | K24: =NetworkingLESS!X24 -> 0.66067427 | L24: =NetworkingLESS!AE24 -> 0.16293883 | N24: =NetworkingLESS!K24 -> 530.86 | O24: =NetworkingLESS!S24 -> 860.19 | P24: =NetworkingLESS!AA24 -> 3966.14 | Q24: =NetworkingLESS!AH24 -> 39025.6
A25: 21 | B25: =NetworkingLESS!O25 -> 0.58097829 | C25: =NetworkingLESS!W25 -> 0.56351905 | E25: =NetworkingLESS!K25 -> 672.84 | F25: =NetworkingLESS!S25 -> 1067.24 | G25: =NetworkingLESS!AA25 -> 4425.64 | I25: 21 | J25: =NetworkingLESS!P25 -> 0.6324371 | K25: =NetworkingLESS!X25 -> 0.61712197 | L25: =NetworkingLESS!AE25 -> 0.12280702 | N25: =NetworkingLESS!K25 -> 672.84 | O25: =NetworkingLESS!S25 -> 1067.24 | P25: =NetworkingLESS!AA25 -> 4425.64 | Q25: =NetworkingLESS!AH25 -> 41087.9
A26: Average | B26: =AVERAGE(B20:B25) -> 0.5782083 | C26: =AVERAGE(C20:C25) -> 0.53458927 | E26: =AVERAGE(E20:E25) -> 388.50667 | F26: =AVERAGE(F20:F25) -> 614.77167 | G26: =AVERAGE(G20:G25) -> 3276.89 | I26: Average | J26: =AVERAGE(J20:J25) -> 0.65082604 | K26: =AVERAGE(K20:K25) -> 0.61475285 | L26: =AVERAGE(L20:L25) -> 0.17206242 | N26: =AVERAGE(N20:N25) -> 388.50667 | O26: =AVERAGE(O20:O25) -> 614.77167 | P26: =AVERAGE(P20:P25) -> 3276.89 | Q26: =AVERAGE(Q20:Q25) -> 30988.05

Sheet Net Effect
A2: Instance | B2: Ratio of Objective Value | D2: Instace | E2: Ratio of Objective Value
A3: 1 | B3: =NetworkingLESS!AR5 -> 1.2643678 | D3: 1 | E3: =NetworkingLESS!AU5 -> 1.0904968
A4: 2 | B4: =NetworkingLESS!AR6 -> 1.1815235 | D4: 2 | E4: =NetworkingLESS!AU6 -> 2.1892744
A5: 3 | B5: =NetworkingLESS!AR7 -> 1.9870088 | D5: 3 | E5: =NetworkingLESS!AU7 -> 3.0635853
A6: 4 | B6: =NetworkingLESS!AR8 -> 1.669587 | D6: 4 | E6: =NetworkingLESS!AU8 -> 3.299471
A7: 5 | B7: =NetworkingLESS!AR9 -> 2.3034803 | D7: 5 | E7: =NetworkingLESS!AU9 -> 2.8342973
A8: 6 | B8: =NetworkingLESS!AR10 -> 1.4001526 | D8: 6 | E8: =NetworkingLESS!AU10 -> 1.7958758
A9: 7 | B9: =NetworkingLESS!AR11 -> 1.9103888 | D9: 7 | E9: =NetworkingLESS!AU11 -> 4.7276299
A10: 8 | B10: =NetworkingLESS!AR12 -> 2.1946123 | D10: 8 | E10: =NetworkingLESS!AU12 -> 3.2092535
A11: 9 | B11: =NetworkingLESS!AR13 -> 1.6686743 | D11: 9 | E11: =NetworkingLESS!AU13 -> 3.2540096
A12: 10 | B12: =NetworkingLESS!AR14 -> 2.1977245 | D12: 10 | E12: =NetworkingLESS!AU14 -> 2.2357861
A13: 11 | B13: =NetworkingLESS!AR15 -> 2.4277195 | D13: 11 | E13: =NetworkingLESS!AU15 -> 1.9093339
A14: 12 | B14: =NetworkingLESS!AR16 -> 4.0004588 | D14: 12 | E14: =NetworkingLESS!AU16 -> 3.4347782
